Workbook

Sheet Salary Silp
A1: CAPITAL BRIDGE PRIVATE LIMITED | E1: PAYSLIP
A2: No: 46/1, Thannekubura, Kandy
A3: Email: info@capitalbridge.lk Tel: 081 763 2009
A5: EMPLOYEE INFORMATION | C5: PAY DATE | D5: PAY TYPE | E5: Salary Month
A6: W M H M Weerasinghe | C6: =DATE(YEAR(E6), MONTH(E6), 25) -> 46259 | D6: Monthly | E6: 46235
A7: =IFERROR(INDEX('Employee Master'!$J:$J,MATCH($A$6,'Employee Master'!$A:$A,0)),"") -> 47/7/A | C7: PAYROLL # | D7: NI NUMBER
A8: =IFERROR(INDEX('Employee Master'!$K:$K,MATCH($A$6,'Employee Master'!$A:$A,0)),"") -> Richard Pamunuwa MW | C8: Position: | D8: =IFERROR(INDEX('Employee Master'!$C:$C,MATCH($A$6,'Employee Master'!$A:$A,0)),"") -> Assistant Accountant
A9: =IFERROR(INDEX('Employee Master'!$L:$L, MATCH($A$6, 'Employee Master'!$A:$A, 0)) & ".", "") -> Matale. | C9: Department | D9: =IFERROR(INDEX('Employee Master'!$D:$D,MATCH($A$6,'Employee Master'!$A:$A,0)),"") -> Finance & Accounts
A10: =IFERROR(INDEX('Employee Master'!$N:$N,MATCH($A$6,'Employee Master'!$A:$A,0)),"") -> 076-7597550
C11: Payment Method: | D11: Online
A13: EARNINGS | E13: CURRENT
A14: Basic Salary | E14: =IFERROR(SUMIFS('Salary Data'!$E:$E,'Salary Data'!$A:$A,$E$6,'Salary Data'!$B:$B,$A$6),0) -> 51500
A15: Budgeted Allowances | E15: =IFERROR(SUMIFS('Salary Data'!$F:$F,'Salary Data'!$A:$A,$E$6,'Salary Data'!$B:$B,$A$6),0) -> 3500
A16: Performance Allowances | E16: =IFERROR(SUMIFS('Salary Data'!$G:$G,'Salary Data'!$A:$A,$E$6,'Salary Data'!$B:$B,$A$6),0) -> 21000
A17: Field Allowances | E17: =IFERROR(SUMIFS('Salary Data'!$H:$H,'Salary Data'!$A:$A,$E$6,'Salary Data'!$B:$B,$A$6),0) -> 0
A18: Travelling Allowances | E18: =IFERROR(SUMIFS('Salary Data'!$I:$I,'Salary Data'!$A:$A,$E$6,'Salary Data'!$B:$B,$A$6),0) -> 10000
A19: Bike Maintained Allowance | E19: =IFERROR(SUMIFS('Salary Data'!$J:$J,'Salary Data'!$A:$A,$E$6,'Salary Data'!$B:$B,$A$6),0) -> 0
A20: Phone Allowance | E20: =IFERROR(SUMIFS('Salary Data'!$K:$K,'Salary Data'!$A:$A,$E$6,'Salary Data'!$B:$B,$A$6),0) -> 1000
A21: Incentives | E21: =IFERROR(SUMIFS('Salary Data'!$L:$L,'Salary Data'!$A:$A,$E$6,'Salary Data'!$B:$B,$A$6),0) -> 3000
C22: GROSS PAY | E22: =SUM(E14:E21) -> 90000
A24: DEDUCTIONS | E24: CURRENT
A25: EPF 8% | E25: =IFERROR(SUMIFS('Salary Data'!$N:$N,'Salary Data'!$A:$A,$E$6,'Salary Data'!$B:$B,$A$6),0) -> 4400
A26: Salary Advance | E26: =IFERROR(SUMIFS('Salary Data'!$O:$O,'Salary Data'!$A:$A,$E$6,'Salary Data'!$B:$B,$A$6),0) -> 0
A27: Travelling Advance | E27: =IFERROR(SUMIFS('Salary Data'!$P:$P,'Salary Data'!$A:$A,$E$6,'Salary Data'!$B:$B,$A$6),0) -> 0
A28: Staff Loan | D28: =IFERROR(INDEX('Salary Data'!$Z:$Z,MATCH($E$6&$A$6,'Salary Data'!$AA:$AA,0)),"") -> 6/10 | E28: =IFERROR(SUMIFS('Salary Data'!$Q:$Q,'Salary Data'!$A:$A,$E$6,'Salary Data'!$B:$B,$A$6),0) -> 10000
A29: Staff Loan Interest | E29: =IFERROR(SUMIFS('Salary Data'!$R:$R,'Salary Data'!$A:$A,$E$6,'Salary Data'!$B:$B,$A$6),0) -> 1500
A30: Other Deduction | E30: =IFERROR(SUMIFS('Salary Data'!$S:$S,'Salary Data'!$A:$A,$E$6,'Salary Data'!$B:$B,$A$6),0) -> 0
A31: Incentives Paid | E31: =IFERROR(SUMIFS('Salary Data'!$T:$T,'Salary Data'!$A:$A,$E$6,'Salary Data'!$B:$B,$A$6),0) -> 3000
A32: Paye Tax | E32: =IFERROR(SUMIFS('Salary Data'!$U:$U,'Salary Data'!$A:$A,$E$6,'Salary Data'!$B:$B,$A$6),0) -> 0
C33: TOTAL DEDUCTIONS | E33: =SUM(E25:E32) -> 18900
C35: NET PAY | E35: =E22-E33 -> 71100
C37: Employer Contributions | D37: EPF 12% | E37: =IFERROR(SUMIFS('Salary Data'!$X:$X,'Salary Data'!$A:$A,$E$6,'Salary Data'!$B:$B,$A$6),0) -> 6600
D38: ETF 3% | E38: =IFERROR(SUMIFS('Salary Data'!$Y:$Y,'Salary Data'!$A:$A,$E$6,'Salary Data'!$B:$B,$A$6),0) -> 1650
A43: ___________________________ | D43: ___________________________
A44: Prepared By | D44: Authorized Signature / Director
A46: If you have any questions about this payslip, please contact:
A47: [Capital bridge (Pvt) Ltd, Email: info@capitalbridge.lk Tel: 081 763 2009]

Sheet Employee Master
A1: Employee Name | B1: EPF No | C1: Designation | D1: Department | E1: Employment From | F1: Employment To | G1: NIC | H1: Age | I1: Address | J1: Address 01 | K1: Address 02 | L1: Address 03 | M1: Email | N1: Phone Number | O1: Active
A2: R A A S Ranasinghe | B2: 5 | C2: Director | D2: Executive Management | E2: 44197 | F2: =EDATE(DATE(IF(LEN(G2)=10, 1900+VALUE(MID(G2,1,2)), VALUE(MID(G2,1,4))), 1, VALUE(IF(LEN(G2)=10, MID(G2,3,3), MID(G2,5,3))) - IF(VALUE(IF(LEN(G2)=10, MID(G2,3,3), MID(G2,5,3)))>500, 500, 0)), 60*12) -> 50174 | G2: 771340318V | H2: =DATEDIF(DATE(IF(LEN(G2)=10, 1900+VALUE(MID(G2,1,2)), VALUE(MID(G2,1,4))), 1, VALUE(IF(LEN(G2)=10, MID(G2,3,3), MID(G2,5,3))) - IF(VALUE(IF(LEN(G2)=10, MID(G2,3,3), MID(G2,5,3)))>500, 500, 0)), TODAY(), "Y") -> 49 | I2: 3/1,Mawath 02, Aruppola, Kandy | J2: 32 | K2: Pikakanda Rd | L2: Kandy | N2: 077-2984772 | O2: Yes
A3: P G U N Wimalasooriya | B3: 10 | C3: Account Assistant | D3: Finance & Accounts | E3: 44927 | F3: =EDATE(DATE(IF(LEN(G3)=10, 1900+VALUE(MID(G3,1,2)), VALUE(MID(G3,1,4))), 1, VALUE(IF(LEN(G3)=10, MID(G3,3,3), MID(G3,5,3))) - IF(VALUE(IF(LEN(G3)=10, MID(G3,3,3), MID(G3,5,3)))>500, 500, 0)), 60*12) -> 58138 | G3: 995632985V | H3: =DATEDIF(DATE(IF(LEN(G3)=10, 1900+VALUE(MID(G3,1,2)), VALUE(MID(G3,1,4))), 1, VALUE(IF(LEN(G3)=10, MID(G3,3,3), MID(G3,5,3))) - IF(VALUE(IF(LEN(G3)=10, MID(G3,3,3), MID(G3,5,3)))>500, 500, 0)), TODAY(), "Y") -> 27 | I3: 218/C/1,Pahala Kondadeniya,Katugastota | J3: 218/C/1 | K3: Pahala Kondadeniya | L3: Katugastota | N3: 076-6447690 | O3: Yes
A4: N M A G M Peiris | B4: 16 | C4: Assistant Branch Maneger | D4: Loan Operations & Field | E4: 45524 | F4: =EDATE(DATE(IF(LEN(G4)=10, 1900+VALUE(MID(G4,1,2)), VALUE(MID(G4,1,4))), 1, VALUE(IF(LEN(G4)=10, MID(G4,3,3), MID(G4,5,3))) - IF(VALUE(IF(LEN(G4)=10, MID(G4,3,3), MID(G4,5,3)))>500, 500, 0)), 60*12) -> 55305 | G4: 911520591V | H4: =DATEDIF(DATE(IF(LEN(G4)=10, 1900+VALUE(MID(G4,1,2)), VALUE(MID(G4,1,4))), 1, VALUE(IF(LEN(G4)=10, MID(G4,3,3), MID(G4,5,3))) - IF(VALUE(IF(LEN(G4)=10, MID(G4,3,3), MID(G4,5,3)))>500, 500, 0)), TODAY(), "Y") -> 35 | I4: 104/2,Walgama,Handessa | J4: 104/2 | K4: Walgama | L4: Handessa | N4: 076-8090400 | O4: Yes
A5: K R T Hemantha | B5: 17 | C5: Field Executive | D5: Loan Operations & Field | E5: 45607 | F5: =EDATE(DATE(IF(LEN(G5)=10, 1900+VALUE(MID(G5,1,2)), VALUE(MID(G5,1,4))), 1, VALUE(IF(LEN(G5)=10, MID(G5,3,3), MID(G5,5,3))) - IF(VALUE(IF(LEN(G5)=10, MID(G5,3,3), MID(G5,5,3)))>500, 500, 0)), 60*12) -> 56635 | G5: 950211385V | H5: =DATEDIF(DATE(IF(LEN(G5)=10, 1900+VALUE(MID(G5,1,2)), VALUE(MID(G5,1,4))), 1, VALUE(IF(LEN(G5)=10, MID(G5,3,3), MID(G5,5,3))) - IF(VALUE(IF(LEN(G5)=10, MID(G5,3,3), MID(G5,5,3)))>500, 500, 0)), TODAY(), "Y") -> 31 | I5: 45/17,Nuwarathanna Rd,Waththegama | J5: 45/17 | K5: Nuwarathanna Rd | L5: Waththegama | N5: 074-3910206 | O5: Yes
A6: W M H M Weerasinghe | B6: 18 | C6: Assistant Accountant | D6: Finance & Accounts | E6: 45628 | F6: =EDATE(DATE(IF(LEN(G6)=10, 1900+VALUE(MID(G6,1,2)), VALUE(MID(G6,1,4))), 1, VALUE(IF(LEN(G6)=10, MID(G6,3,3), MID(G6,5,3))) - IF(VALUE(IF(LEN(G6)=10, MID(G6,3,3), MID(G6,5,3)))>500, 500, 0)), 60*12) -> 58326 | G6: 992512156V | H6: =DATEDIF(DATE(IF(LEN(G6)=10, 1900+VALUE(MID(G6,1,2)), VALUE(MID(G6,1,4))), 1, VALUE(IF(LEN(G6)=10, MID(G6,3,3), MID(G6,5,3))) - IF(VALUE(IF(LEN(G6)=10, MID(G6,3,3), MID(G6,5,3)))>500, 500, 0)), TODAY(), "Y") -> 27 | I6: 47/7/A,Richard Pamunuwa MW,Matale | J6: 47/7/A | K6: Richard Pamunuwa MW | L6: Matale | N6: 076-7597550 | O6: Yes
A7: R W D S Wijerathna | B7: 19 | C7: Field Executive | D7: Loan Operations & Field | E7: 45642 | F7: =EDATE(DATE(IF(LEN(G7)=10, 1900+VALUE(MID(G7,1,2)), VALUE(MID(G7,1,4))), 1, VALUE(IF(LEN(G7)=10, MID(G7,3,3), MID(G7,5,3))) - IF(VALUE(IF(LEN(G7)=10, MID(G7,3,3), MID(G7,5,3)))>500, 500, 0)), 60*12) -> 53780 | G7: 198708803218 | H7: =DATEDIF(DATE(IF(LEN(G7)=10, 1900+VALUE(MID(G7,1,2)), VALUE(MID(G7,1,4))), 1, VALUE(IF(LEN(G7)=10, MID(G7,3,3), MID(G7,5,3))) - IF(VALUE(IF(LEN(G7)=10, MID(G7,3,3), MID(G7,5,3)))>500, 500, 0)), TODAY(), "Y") -> 39 | I7: 19/1,Thannekubura,Kandy | J7: 19/1 | K7: Thannekubura | L7: Kandy | N7: 074-3365562 | O7: Yes
A8: S Wathmi Sankalpana | B8: 21 | C8: Trainee Account Clark | D8: Back Office | E8: 45659 | F8: =EDATE(DATE(IF(LEN(G8)=10, 1900+VALUE(MID(G8,1,2)), VALUE(MID(G8,1,4))), 1, VALUE(IF(LEN(G8)=10, MID(G8,3,3), MID(G8,5,3))) - IF(VALUE(IF(LEN(G8)=10, MID(G8,3,3), MID(G8,5,3)))>500, 500, 0)), 60*12) -> 60015 | G8: 200461403626 | H8: =DATEDIF(DATE(IF(LEN(G8)=10, 1900+VALUE(MID(G8,1,2)), VALUE(MID(G8,1,4))), 1, VALUE(IF(LEN(G8)=10, MID(G8,3,3), MID(G8,5,3))) - IF(VALUE(IF(LEN(G8)=10, MID(G8,3,3), MID(G8,5,3)))>500, 500, 0)), TODAY(), "Y") -> 22 | I8: 54,Alhena,Katawala Lewla | J8: 54 | K8: Alhena | L8: Katawala, Lewla | N8: 077-2745896 | O8: Yes
A9: E M P P W O R K Jayawardana | B9: 22 | C9: Trainee Field Executive | D9: Loan Operations & Field | E9: 45779 | F9: =EDATE(DATE(IF(LEN(G9)=10, 1900+VALUE(MID(G9,1,2)), VALUE(MID(G9,1,4))), 1, VALUE(IF(LEN(G9)=10, MID(G9,3,3), MID(G9,5,3))) - IF(VALUE(IF(LEN(G9)=10, MID(G9,3,3), MID(G9,5,3)))>500, 500, 0)), 60*12) -> 59970 | G9: 200406911756 | H9: =DATEDIF(DATE(IF(LEN(G9)=10, 1900+VALUE(MID(G9,1,2)), VALUE(MID(G9,1,4))), 1, VALUE(IF(LEN(G9)=10, MID(G9,3,3), MID(G9,5,3))) - IF(VALUE(IF(LEN(G9)=10, MID(G9,3,3), MID(G9,5,3)))>500, 500, 0)), TODAY(), "Y") -> 22 | I9: 103,Watapana,Putuhapuwa | J9: 103 | K9: Watapana | L9: Putuhapuwa | N9: 071-1074470 | O9: Yes
A10: T M R L B Thennakoon | B10: 23 | C10: Trainee Field Executive | D10: Loan Operations & Field | E10: 45845 | F10: =EDATE(DATE(IF(LEN(G10)=10, 1900+VALUE(MID(G10,1,2)), VALUE(MID(G10,1,4))), 1, VALUE(IF(LEN(G10)=10, MID(G10,3,3), MID(G10,5,3))) - IF(VALUE(IF(LEN(G10)=10, MID(G10,3,3), MID(G10,5,3)))>500, 500, 0)), 60*12) -> 60221 | G10: 200432000572 | H10: =DATEDIF(DATE(IF(LEN(G10)=10, 1900+VALUE(MID(G10,1,2)), VALUE(MID(G10,1,4))), 1, VALUE(IF(LEN(G10)=10, MID(G10,3,3), MID(G10,5,3))) - IF(VALUE(IF(LEN(G10)=10, MID(G10,3,3), MID(G10,5,3)))>500, 500, 0)), TODAY(), "Y") -> 21 | I10: No. 133/2, Nugepathana, Watapana, Putuhapuwa | J10: 133/2 | K10: Nugepathana | L10: Watapana, Putuhapuwa | N10: 072-7647478 | O10: Yes
A11: W K Senaverathna | B11: 24 | C11: Field Executive | D11: Loan Operations & Field | E11: 45875 | F11: =EDATE(DATE(IF(LEN(G11)=10, 1900+VALUE(MID(G11,1,2)), VALUE(MID(G11,1,4))), 1, VALUE(IF(LEN(G11)=10, MID(G11,3,3), MID(G11,5,3))) - IF(VALUE(IF(LEN(G11)=10, MID(G11,3,3), MID(G11,5,3)))>500, 500, 0)), 60*12) -> 57620 | G11: 972753432V | H11: =DATEDIF(DATE(IF(LEN(G11)=10, 1900+VALUE(MID(G11,1,2)), VALUE(MID(G11,1,4))), 1, VALUE(IF(LEN(G11)=10, MID(G11,3,3), MID(G11,5,3))) - IF(VALUE(IF(LEN(G11)=10, MID(G11,3,3), MID(G11,5,3)))>500, 500, 0)), TODAY(), "Y") -> 29 | I11: 173/1,Palkubura,Madawala,Harispaththuwa | J11: 173/1 | K11: Palkubura | L11: Madawala, Harispaththuwa | N11: 077-8115364 | O11: Yes
A12: D R G S L Ranaweera | B12: 25 | C12: Field Executive | D12: Loan Operations & Field | E12: 45937 | F12: =EDATE(DATE(IF(LEN(G12)=10, 1900+VALUE(MID(G12,1,2)), VALUE(MID(G12,1,4))), 1, VALUE(IF(LEN(G12)=10, MID(G12,3,3), MID(G12,5,3))) - IF(VALUE(IF(LEN(G12)=10, MID(G12,3,3), MID(G12,5,3)))>500, 500, 0)), 60*12) -> 59698 | G12: 200316201041 | H12: =DATEDIF(DATE(IF(LEN(G12)=10, 1900+VALUE(MID(G12,1,2)), VALUE(MID(G12,1,4))), 1, VALUE(IF(LEN(G12)=10, MID(G12,3,3), MID(G12,5,3))) - IF(VALUE(IF(LEN(G12)=10, MID(G12,3,3), MID(G12,5,3)))>500, 500, 0)), TODAY(), "Y") -> 23 | I12: 29/4,Ullandupitiya,Werellagama,Kandy | J12: 29/4 | K12: Ullandupitiya | L12: Werellagama, Kandy | N12: 074-2618166 | O12: Yes
A13: W A A Heshani Bandara | B13: 26 | C13: Trainee Account Clark | D13: Back Office | E13: 45971 | F13: =EDATE(DATE(IF(LEN(G13)=10, 1900+VALUE(MID(G13,1,2)), VALUE(MID(G13,1,4))), 1, VALUE(IF(LEN(G13)=10, MID(G13,3,3), MID(G13,5,3))) - IF(VALUE(IF(LEN(G13)=10, MID(G13,3,3), MID(G13,5,3)))>500, 500, 0)), 60*12) -> 60487 | G13: 200572003817 | H13: =DATEDIF(DATE(IF(LEN(G13)=10, 1900+VALUE(MID(G13,1,2)), VALUE(MID(G13,1,4))), 1, VALUE(IF(LEN(G13)=10, MID(G13,3,3), MID(G13,5,3))) - IF(VALUE(IF(LEN(G13)=10, MID(G13,3,3), MID(G13,5,3)))>500, 500, 0)), TODAY(), "Y") -> 21 | I13: 42/A,Haragama,Gurudeniya | J13: 42/A | K13: Haragama | L13: Gurudeniya | N13: 071-7297769 | O13: Yes
A14: D M T S Disanayake | B14: 27 | C14: Trainee Field Executive | D14: Loan Operations & Field | E14: 45978 | F14: =EDATE(DATE(IF(LEN(G14)=10, 1900+VALUE(MID(G14,1,2)), VALUE(MID(G14,1,4))), 1, VALUE(IF(LEN(G14)=10, MID(G14,3,3), MID(G14,5,3))) - IF(VALUE(IF(LEN(G14)=10, MID(G14,3,3), MID(G14,5,3)))>500, 500, 0)), 60*12) -> 60603 | G14: 200533602082 | H14: =DATEDIF(DATE(IF(LEN(G14)=10, 1900+VALUE(MID(G14,1,2)), VALUE(MID(G14,1,4))), 1, VALUE(IF(LEN(G14)=10, MID(G14,3,3), MID(G14,5,3))) - IF(VALUE(IF(LEN(G14)=10, MID(G14,3,3), MID(G14,5,3)))>500, 500, 0)), TODAY(), "Y") -> 20 | I14: 165/1,Amunugama,Gunnapana | J14: 165/1 | K14: Amunugama | L14: Gunnapana | N14: 075-0872988 | O14: Yes
A15: P L D B Wijewardhna | B15: 28 | C15: Field Executive | D15: Back Office | E15: 46023 | F15: =EDATE(DATE(IF(LEN(G15)=10, 1900+VALUE(MID(G15,1,2)), VALUE(MID(G15,1,4))), 1, VALUE(IF(LEN(G15)=10, MID(G15,3,3), MID(G15,5,3))) - IF(VALUE(IF(LEN(G15)=10, MID(G15,3,3), MID(G15,5,3)))>500, 500, 0)), 60*12) -> 57148 | G15: 199616902059 | H15: =DATEDIF(DATE(IF(LEN(G15)=10, 1900+VALUE(MID(G15,1,2)), VALUE(MID(G15,1,4))), 1, VALUE(IF(LEN(G15)=10, MID(G15,3,3), MID(G15,5,3))) - IF(VALUE(IF(LEN(G15)=10, MID(G15,3,3), MID(G15,5,3)))>500, 500, 0)), TODAY(), "Y") -> 30 | I15: 166,Jayabima,Arabegama,Werellagama | J15: 166 | K15: Jayabima | L15: Arabegama, Werellagama | N15: 077-6508664 | O15: Yes
A16: N G L D Supunsiri | B16: 29 | C16: Trainee Field Executive | D16: Loan Operations & Field | E16: 46104 | F16: =EDATE(DATE(IF(LEN(G16)=10, 1900+VALUE(MID(G16,1,2)), VALUE(MID(G16,1,4))), 1, VALUE(IF(LEN(G16)=10, MID(G16,3,3), MID(G16,5,3))) - IF(VALUE(IF(LEN(G16)=10, MID(G16,3,3), MID(G16,5,3)))>500, 500, 0)), 60*12) -> 60377 | G16: 200511002229 | H16: =DATEDIF(DATE(IF(LEN(G16)=10, 1900+VALUE(MID(G16,1,2)), VALUE(MID(G16,1,4))), 1, VALUE(IF(LEN(G16)=10, MID(G16,3,3), MID(G16,5,3))) - IF(VALUE(IF(LEN(G16)=10, MID(G16,3,3), MID(G16,5,3)))>500, 500, 0)), TODAY(), "Y") -> 21 | I16: 04, Hathmunna, Pilawala | J16: 4 | K16: Hathmunna | L16: Pilawala | N16: 077-6672131 | O16: Yes

Sheet Salary Data
A1: Month | B1: Employee Name | C1: EPF No | D1: Designation | E1: Basic Salary | F1: Budgeted Allowance | G1: Performance Allowance | H1: Field Allowance | I1: Travelling Allowance | J1: Bike Maintenance | K1: Phone Allowance | L1: Incentives | M1: Gross Salary | N1: EPF 8% | O1: Salary Advance | P1: Travelling Advance | Q1: Staff Loan | R1: Staff Loan Interest | S1: Other Deduction | T1: Incentives Paid | U1: PAYE Tax | V1: Total Deduction | W1: Net Salary | X1: EPF 12% | Y1: ETF 3% | Z1: Loan Instalement | AA1: Loan Instalement
A2: 46113 | B2: R A A S Ranasinghe | C2: 5 | D2: Director | E2: 61500 | F2: 3500 | G2: 53000 | H2: 0 | I2: 29000 | J2: 30000 | K2: 1000 | L2: 0 | M2: =SUM(E2:L2) -> 178000 | N2: =(E2+F2)*8% -> 5200 | O2: 0 | P2: 0 | Q2: 9250 | R2: 3700 | S2: 0 | T2: 0 | U2: 1680 | V2: =SUM(N2:U2) -> 19830 | W2: =M2-V2 -> 158170 | X2: =(E2+F2)*12% -> 7800 | Y2: =(E2+F2)*3% -> 1950 | Z2: 20/1 | AA2: =A2&B2 -> 46113R A A S Ranasinghe
A3: 46113 | B3: P G U N Wimalasooriya | C3: 10 | D3: Account Assistant | E3: 26500 | F3: 3500 | G3: 5000 | H3: 0 | I3: 7000 | J3: 0 | K3: 1000 | L3: 2000 | M3: =SUM(E3:L3) -> 45000 | N3: =(E3+F3)*8% -> 2400 | O3: 0 | P3: 0 | Q3: 10000 | R3: 600 | S3: 0 | T3: 2000 | U3: 0 | V3: =SUM(N3:U3) -> 15000 | W3: =M3-V3 -> 30000 | X3: =(E3+F3)*12% -> 3600 | Y3: =(E3+F3)*3% -> 900 | Z3: 2/3 | AA3: =A3&B3 -> 46113P G U N Wimalasooriya
A4: 46113 | B4: N M A G M Peiris | C4: 16 | D4: Assistant Branch Maneger | E4: 41500 | F4: 3500 | G4: 17000 | H4: 8000 | I4: 24360 | J4: 0 | K4: 1000 | L4: 3050 | M4: =SUM(E4:L4) -> 98410 | N4: =(E4+F4)*8% -> 3600 | O4: 10000 | P4: 0 | Q4: 12500 | R4: 750 | S4: 0 | T4: 3050 | U4: 0 | V4: =SUM(N4:U4) -> 29900 | W4: =M4-V4 -> 68510 | X4: =(E4+F4)*12% -> 5400 | Y4: =(E4+F4)*3% -> 1350 | Z4: 7/8 | AA4: =A4&B4 -> 46113N M A G M Peiris
A5: 46113 | B5: K R T Hemantha | C5: 17 | D5: Field Executive | E5: 31500 | F5: 3500 | G5: 7500 | H5: 5000 | I5: 24360 | J5: 10000 | K5: 1000 | L5: 3915 | M5: =SUM(E5:L5) -> 86775 | N5: =(E5+F5)*8% -> 2800 | O5: 12000 | P5: 0 | Q5: 10000 | R5: 1500 | S5: 0 | T5: 3915 | U5: 0 | V5: =SUM(N5:U5) -> 30215 | W5: =M5-V5 -> 56560 | X5: =(E5+F5)*12% -> 4200 | Y5: =(E5+F5)*3% -> 1050 | Z5: 3/7 | AA5: =A5&B5 -> 46113K R T Hemantha
A6: 46113 | B6: W M H M Weerasinghe | C6: 18 | D6: Assistant Accountant | E6: 51500 | F6: 3500 | G6: 21000 | H6: 0 | I6: 10000 | J6: 0 | K6: 1000 | L6: 2000 | M6: =SUM(E6:L6) -> 89000 | N6: =(E6+F6)*8% -> 4400 | O6: 0 | P6: 0 | Q6: 10000 | R6: 2700 | S6: 0 | T6: 2000 | U6: 0 | V6: =SUM(N6:U6) -> 19100 | W6: =M6-V6 -> 69900 | X6: =(E6+F6)*12% -> 6600 | Y6: =(E6+F6)*3% -> 1650 | Z6: 2/10 | AA6: =A6&B6 -> 46113W M H M Weerasinghe
A7: 46113 | B7: R W D S Wijerathna | C7: 19 | D7: Field Executive | E7: 36500 | F7: 3500 | G7: 7500 | H7: 5000 | I7: 24360 | J7: 10000 | K7: 1000 | L7: 11500 | M7: =SUM(E7:L7) -> 99360 | N7: =(E7+F7)*8% -> 3200 | O7: 0 | P7: 0 | Q7: 8333.33 | R7: 1500 | S7: 0 | T7: 11500 | U7: 0 | V7: =SUM(N7:U7) -> 24533.33 | W7: =M7-V7 -> 74826.67 | X7: =(E7+F7)*12% -> 4800 | Y7: =(E7+F7)*3% -> 1200 | Z7: 7/12 | AA7: =A7&B7 -> 46113R W D S Wijerathna
A8: 46113 | B8: S Wathmi Sankalpana | C8: 21 | D8: Trainee Account Clark | E8: 26500 | F8: 3500 | G8: 0 | H8: 0 | I8: 5000 | J8: 0 | K8: 1000 | L8: 2000 | M8: =SUM(E8:L8) -> 38000 | N8: =(E8+F8)*8% -> 2400 | O8: 0 | P8: 0 | Q8: 6000 | R8: 900 | S8: 0 | T8: 2000 | U8: 0 | V8: =SUM(N8:U8) -> 11300 | W8: =M8-V8 -> 26700 | X8: =(E8+F8)*12% -> 3600 | Y8: =(E8+F8)*3% -> 900 | Z8: 1/5 | AA8: =A8&B8 -> 46113S Wathmi Sankalpana
A9: 46113 | B9: E M P P W O R K Jayawardana | C9: 22 | D9: Trainee Field Executive | E9: 26500 | F9: 3500 | G9: 5000 | H9: 2760 | I9: 20880 | J9: 10000 | K9: 1000 | L9: 10175 | M9: =SUM(E9:L9) -> 79815 | N9: =(E9+F9)*8% -> 2400 | O9: 0 | P9: 0 | Q9: 5000 | R9: 2400 | S9: 0 | T9: 10175 | U9: 0 | V9: =SUM(N9:U9) -> 19975 | W9: =M9-V9 -> 59840 | X9: =(E9+F9)*12% -> 3600 | Y9: =(E9+F9)*3% -> 900 | Z9: 1/16 | AA9: =A9&B9 -> 46113E M P P W O R K Jayawardana
A10: 46113 | B10: T M R L B Thennakoon | C10: 23 | D10: Trainee Field Executive | E10: 26500 | F10: 3500 | G10: 7000 | H10: 5000 | I10: 20880 | J10: 0 | K10: 1000 | L10: 6272.5 | M10: =SUM(E10:L10) -> 70152.5 | N10: =(E10+F10)*8% -> 2400 | O10: 0 | P10: 0 | Q10: 10000 | R10: 1200 | S10: 0 | T10: 6272.5 | U10: 0 | V10: =SUM(N10:U10) -> 19872.5 | W10: =M10-V10 -> 50280 | X10: =(E10+F10)*12% -> 3600 | Y10: =(E10+F10)*3% -> 900 | Z10: 2/5 | AA10: =A10&B10 -> 46113T M R L B Thennakoon
A11: 46113 | B11: W K Senaverathna | C11: 24 | D11: Field Executive | E11: 31500 | F11: 3500 | G11: 7500 | H11: 5000 | I11: 20880 | J11: 0 | K11: 1000 | L11: 14525 | M11: =SUM(E11:L11) -> 83905 | N11: =(E11+F11)*8% -> 2800 | O11: 0 | P11: 0 | Q11: 0 | R11: 0 | S11: 0 | T11: 14525 | U11: 0 | V11: =SUM(N11:U11) -> 17325 | W11: =M11-V11 -> 66580 | X11: =(E11+F11)*12% -> 4200 | Y11: =(E11+F11)*3% -> 1050 | AA11: =A11&B11 -> 46113W K Senaverathna
A12: 46113 | B12: D R G S L Ranaweera | C12: 25 | D12: Field Executive | E12: 36500 | F12: 3500 | G12: 5000 | H12: 5000 | I12: 22620 | J12: 10000 | K12: 1000 | L12: 10650 | M12: =SUM(E12:L12) -> 94270 | N12: =(E12+F12)*8% -> 3200 | O12: 15000 | P12: 0 | Q12: 0 | R12: 0 | S12: 0 | T12: 10650 | U12: 0 | V12: =SUM(N12:U12) -> 28850 | W12: =M12-V12 -> 65420 | X12: =(E12+F12)*12% -> 4800 | Y12: =(E12+F12)*3% -> 1200 | AA12: =A12&B12 -> 46113D R G S L Ranaweera
A13: 46113 | B13: W A A Heshani Bandara | C13: 26 | D13: Trainee Account Clark | E13: 26500 | F13: 3500 | G13: 0 | H13: 0 | I13: 0 | J13: 0 | K13: 1000 | L13: 2000 | M13: =SUM(E13:L13) -> 33000 | N13: =(E13+F13)*8% -> 2400 | O13: 0 | P13: 0 | Q13: 0 | R13: 0 | S13: 0 | T13: 2000 | U13: 0 | V13: =SUM(N13:U13) -> 4400 | W13: =M13-V13 -> 28600 | X13: =(E13+F13)*12% -> 3600 | Y13: =(E13+F13)*3% -> 900 | AA13: =A13&B13 -> 46113W A A Heshani Bandara
A14: 46113 | B14: D M T S Disanayake | C14: 27 | D14: Trainee Field Executive | E14: 26500 | F14: 3500 | G14: 2500 | H14: 2500 | I14: 17400 | J14: 10000 | K14: 1000 | L14: 9675 | M14: =SUM(E14:L14) -> 73075 | N14: =(E14+F14)*8% -> 2400 | O14: 0 | P14: 0 | Q14: 10000 | R14: 2400 | S14: 0 | T14: 9675 | U14: 0 | V14: =SUM(N14:U14) -> 24475 | W14: =M14-V14 -> 48600 | X14: =(E14+F14)*12% -> 3600 | Y14: =(E14+F14)*3% -> 900 | Z14: 3/10 | AA14: =A14&B14 -> 46113D M T S Disanayake
A15: 46113 | B15: P L D B Wijewardhna | C15: 28 | D15: Field Executive | E15: 36500 | F15: 3500 | G15: 5000 | H15: 5000 | I15: 22620 | J15: 10000 | K15: 1000 | L15: 9272.5 | M15: =SUM(E15:L15) -> 92892.5 | N15: =(E15+F15)*8% -> 3200 | O15: 0 | P15: 0 | Q15: 0 | R15: 0 | S15: 0 | T15: 9272.5 | U15: 0 | V15: =SUM(N15:U15) -> 12472.5 | W15: =M15-V15 -> 80420 | X15: =(E15+F15)*12% -> 4800 | Y15: =(E15+F15)*3% -> 1200 | AA15: =A15&B15 -> 46113P L D B Wijewardhna
A16: 46113 | B16: N G L D Supunsiri | D16: Trainee Field Executive | E16: 0 | F16: 0 | G16: 30000 | H16: 0 | I16: 0 | J16: 0 | K16: 0 | L16: 0 | M16: =SUM(E16:L16) -> 30000 | N16: =(E16+F16)*8% -> 0 | O16: 0 | P16: 0 | Q16: 0 | R16: 0 | S16: 0 | T16: 0 | U16: 0 | V16: =SUM(N16:U16) -> 0 | W16: =M16-V16 -> 30000 | X16: =(E16+F16)*12% -> 0 | Y16: =(E16+F16)*3% -> 0 | AA16: =A16&B16 -> 46113N G L D Supunsiri
A17: 46143 | B17: R A A S Ranasinghe | C17: 5 | D17: Director | E17: 61500 | F17: 3500 | G17: 53000 | H17: 0 | I17: 29000 | J17: 30000 | K17: 1000 | L17: 0 | M17: =SUM(E17:L17) -> 178000 | N17: =(E17+F17)*8% -> 5200 | O17: 70000 | P17: 0 | Q17: 9250 | R17: 3515 | S17: 0 | T17: 0 | U17: 1680 | V17: =SUM(N17:U17) -> 89645 | W17: =M17-V17 -> 88355 | X17: =(E17+F17)*12% -> 7800 | Y17: =(E17+F17)*3% -> 1950 | Z17: 2/20 | AA17: =A17&B17 -> 46143R A A S Ranasinghe
A18: 46143 | B18: P G U N Wimalasooriya | C18: 10 | D18: Account Assistant | E18: 26500 | F18: 3500 | G18: 5000 | H18: 0 | I18: 7000 | J18: 0 | K18: 1000 | L18: 1500 | M18: =SUM(E18:L18) -> 44500 | N18: =(E18+F18)*8% -> 2400 | O18: 10000 | P18: 0 | Q18: 10000 | R18: 300 | S18: 0 | T18: 1500 | U18: 0 | V18: =SUM(N18:U18) -> 24200 | W18: =M18-V18 -> 20300 | X18: =(E18+F18)*12% -> 3600 | Y18: =(E18+F18)*3% -> 900 | Z18: 3/3 | AA18: =A18&B18 -> 46143P G U N Wimalasooriya
A19: 46143 | B19: N M A G M Peiris | C19: 16 | D19: Assistant Branch Maneger | E19: 41500 | F19: 3500 | G19: 17000 | H19: 8000 | I19: 24780 | J19: 0 | K19: 1000 | L19: 1380 | M19: =SUM(E19:L19) -> 97160 | N19: =(E19+F19)*8% -> 3600 | O19: 15000 | P19: 0 | Q19: 12500 | R19: 375 | S19: 0 | T19: 1380 | U19: 0 | V19: =SUM(N19:U19) -> 32855 | W19: =M19-V19 -> 64305 | X19: =(E19+F19)*12% -> 5400 | Y19: =(E19+F19)*3% -> 1350 | Z19: 8/8 | AA19: =A19&B19 -> 46143N M A G M Peiris
A20: 46143 | B20: K R T Hemantha | C20: 17 | D20: Field Executive | E20: 31500 | F20: 3500 | G20: 7500 | H20: 5000 | I20: 24780 | J20: 10000 | K20: 1000 | L20: 3620 | M20: =SUM(E20:L20) -> 86900 | N20: =(E20+F20)*8% -> 2800 | O20: 17000 | P20: 0 | Q20: 10000 | R20: 1200 | S20: 0 | T20: 3620 | U20: 0 | V20: =SUM(N20:U20) -> 34620 | W20: =M20-V20 -> 52280 | X20: =(E20+F20)*12% -> 4200 | Y20: =(E20+F20)*3% -> 1050 | Z20: 4/7 | AA20: =A20&B20 -> 46143K R T Hemantha
A21: 46143 | B21: W M H M Weerasinghe | C21: 18 | D21: Assistant Accountant | E21: 51500 | F21: 3500 | G21: 21000 | H21: 0 | I21: 10000 | J21: 0 | K21: 1000 | L21: 1500 | M21: =SUM(E21:L21) -> 88500 | N21: =(E21+F21)*8% -> 4400 | O21: 0 | P21: 0 | Q21: 10000 | R21: 2400 | S21: 0 | T21: 1500 | U21: 0 | V21: =SUM(N21:U21) -> 18300 | W21: =M21-V21 -> 70200 | X21: =(E21+F21)*12% -> 6600 | Y21: =(E21+F21)*3% -> 1650 | Z21: 3/10 | AA21: =A21&B21 -> 46143W M H M Weerasinghe
A22: 46143 | B22: R W D S Wijerathna | C22: 19 | D22: Field Executive | E22: 36500 | F22: 3500 | G22: 7500 | H22: 5000 | I22: 24780 | J22: 10000 | K22: 1000 | L22: 10000 | M22: =SUM(E22:L22) -> 98280 | N22: =(E22+F22)*8% -> 3200 | O22: 0 | P22: 0 | Q22: 8333.33 | R22: 1250 | S22: 0 | T22: 10000 | U22: 0 | V22: =SUM(N22:U22) -> 22783.33 | W22: =M22-V22 -> 75496.67 | X22: =(E22+F22)*12% -> 4800 | Y22: =(E22+F22)*3% -> 1200 | Z22: 8/12 | AA22: =A22&B22 -> 46143R W D S Wijerathna
A23: 46143 | B23: S Wathmi Sankalpana | C23: 21 | D23: Trainee Account Clark | E23: 26500 | F23: 3500 | G23: 0 | H23: 0 | I23: 5000 | J23: 0 | K23: 1000 | L23: 1500 | M23: =SUM(E23:L23) -> 37500 | N23: =(E23+F23)*8% -> 2400 | O23: 2000 | P23: 0 | Q23: 6000 | R23: 720 | S23: 0 | T23: 1500 | U23: 0 | V23: =SUM(N23:U23) -> 12620 | W23: =M23-V23 -> 24880 | X23: =(E23+F23)*12% -> 3600 | Y23: =(E23+F23)*3% -> 900 | Z23: 2/5 | AA23: =A23&B23 -> 46143S Wathmi Sankalpana
A24: 46143 | B24: E M P P W O R K Jayawardana | C24: 22 | D24: Trainee Field Executive | E24: 26500 | F24: 3500 | G24: 5000 | H24: 2760 | I24: 21240 | J24: 10000 | K24: 1000 | L24: 8000 | M24: =SUM(E24:L24) -> 78000 | N24: =(E24+F24)*8% -> 2400 | O24: 6000 | P24: 0 | Q24: 5000 | R24: 2250 | S24: 0 | T24: 8000 | U24: 0 | V24: =SUM(N24:U24) -> 23650 | W24: =M24-V24 -> 54350 | X24: =(E24+F24)*12% -> 3600 | Y24: =(E24+F24)*3% -> 900 | Z24: 2/16 | AA24: =A24&B24 -> 46143E M P P W O R K Jayawardana
A25: 46143 | B25: T M R L B Thennakoon | C25: 23 | D25: Trainee Field Executive | E25: 26500 | F25: 3500 | G25: 7000 | H25: 5000 | I25: 21240 | J25: 0 | K25: 1000 | L25: 1720 | M25: =SUM(E25:L25) -> 65960 | N25: =(E25+F25)*8% -> 2400 | O25: 6000 | P25: 0 | Q25: 10000 | R25: 900 | S25: 0 | T25: 1720 | U25: 0 | V25: =SUM(N25:U25) -> 21020 | W25: =M25-V25 -> 44940 | X25: =(E25+F25)*12% -> 3600 | Y25: =(E25+F25)*3% -> 900 | Z25: 3/5 | AA25: =A25&B25 -> 46143T M R L B Thennakoon
A26: 46143 | B26: W K Senaverathna | C26: 24 | D26: Field Executive | E26: 31500 | F26: 3500 | G26: 7500 | H26: 5000 | I26: 21240 | J26: 0 | K26: 1000 | L26: 11420 | M26: =SUM(E26:L26) -> 81160 | N26: =(E26+F26)*8% -> 2800 | O26: 0 | P26: 0 | Q26: 0 | R26: 0 | S26: 0 | T26: 11420 | U26: 0 | V26: =SUM(N26:U26) -> 14220 | W26: =M26-V26 -> 66940 | X26: =(E26+F26)*12% -> 4200 | Y26: =(E26+F26)*3% -> 1050 | AA26: =A26&B26 -> 46143W K Senaverathna
A27: 46143 | B27: D R G S L Ranaweera | C27: 25 | D27: Field Executive | E27: 36500 | F27: 3500 | G27: 5000 | H27: 5000 | I27: 23010 | J27: 10000 | K27: 1000 | L27: 7475 | M27: =SUM(E27:L27) -> 91485 | N27: =(E27+F27)*8% -> 3200 | O27: 15000 | P27: 0 | Q27: 10000 | R27: 1800 | S27: 0 | T27: 7475 | U27: 0 | V27: =SUM(N27:U27) -> 37475 | W27: =M27-V27 -> 54010 | X27: =(E27+F27)*12% -> 4800 | Y27: =(E27+F27)*3% -> 1200 | Z27: 1/6 | AA27: =A27&B27 -> 46143D R G S L Ranaweera
A28: 46143 | B28: W A A Heshani Bandara | C28: 26 | D28: Trainee Account Clark | E28: 26500 | F28: 3500 | G28: 0 | H28: 0 | I28: 0 | J28: 0 | K28: 1000 | L28: 1500 | M28: =SUM(E28:L28) -> 32500 | N28: =(E28+F28)*8% -> 2400 | O28: 0 | P28: 0 | Q28: 0 | R28: 0 | S28: 0 | T28: 1500 | U28: 0 | V28: =SUM(N28:U28) -> 3900 | W28: =M28-V28 -> 28600 | X28: =(E28+F28)*12% -> 3600 | Y28: =(E28+F28)*3% -> 900 | AA28: =A28&B28 -> 46143W A A Heshani Bandara
A29: 46143 | B29: D M T S Disanayake | C29: 27 | D29: Trainee Field Executive | E29: 26500 | F29: 3500 | G29: 2500 | H29: 2500 | I29: 17700 | J29: 10000 | K29: 1000 | L29: 4560 | M29: =SUM(E29:L29) -> 68260 | N29: =(E29+F29)*8% -> 2400 | O29: 5000 | P29: 0 | Q29: 10000 | R29: 2100 | S29: 0 | T29: 4560 | U29: 0 | V29: =SUM(N29:U29) -> 24060 | W29: =M29-V29 -> 44200 | X29: =(E29+F29)*12% -> 3600 | Y29: =(E29+F29)*3% -> 900 | Z29: 4/10 | AA29: =A29&B29 -> 46143D M T S Disanayake
A30: 46143 | B30: P L D B Wijewardhna | C30: 28 | D30: Field Executive | E30: 36500 | F30: 3500 | G30: 5000 | H30: 5000 | I30: 23010 | J30: 10000 | K30: 1000 | L30: 5000 | M30: =SUM(E30:L30) -> 89010 | N30: =(E30+F30)*8% -> 3200 | O30: 5000 | P30: 0 | Q30: 0 | R30: 0 | S30: 0 | T30: 5000 | U30: 0 | V30: =SUM(N30:U30) -> 13200 | W30: =M30-V30 -> 75810 | X30: =(E30+F30)*12% -> 4800 | Y30: =(E30+F30)*3% -> 1200 | AA30: =A30&B30 -> 46143P L D B Wijewardhna
A31: 46143 | B31: N G L D Supunsiri | D31: Trainee Field Executive | E31: 26500 | F31: 3500 | G31: 5000 | H31: 5000 | I31: 14160 | J31: 0 | K31: 1000 | L31: 0 | M31: =SUM(E31:L31) -> 55160 | N31: =(E31+F31)*8% -> 2400 | O31: 6000 | P31: 0 | Q31: 0 | R31: 0 | S31: 0 | T31: 0 | U31: 0 | V31: =SUM(N31:U31) -> 8400 | W31: =M31-V31 -> 46760 | X31: =(E31+F31)*12% -> 3600 | Y31: =(E31+F31)*3% -> 900 | AA31: =A31&B31 -> 46143N G L D Supunsiri
A32: 46174 | B32: R A A S Ranasinghe | C32: 5 | D32: Director | E32: 61500 | F32: 3500 | G32: 53000 | H32: 0 | I32: 29000 | J32: 30000 | K32: 1000 | L32: 0 | M32: =SUM(E32:L32) -> 178000 | N32: =(E32+F32)*8% -> 5200 | O32: 50000 | P32: 0 | Q32: 9250 | R32: 3330 | S32: 0 | T32: 0 | U32: 1680 | V32: =SUM(N32:U32) -> 69460 | W32: =M32-V32 -> 108540 | X32: =(E32+F32)*12% -> 7800 | Y32: =(E32+F32)*3% -> 1950 | Z32: 3/20 | AA32: =A32&B32 -> 46174R A A S Ranasinghe
A33: 46174 | B33: P G U N Wimalasooriya | C33: 10 | D33: Account Assistant | E33: 26500 | F33: 3500 | G33: 5000 | H33: 0 | I33: 7000 | J33: 0 | K33: 1000 | L33: 1000 | M33: =SUM(E33:L33) -> 44000 | N33: =(E33+F33)*8% -> 2400 | O33: 0 | P33: 0 | Q33: 10000 | R33: 900 | S33: 0 | T33: 1000 | U33: 0 | V33: =SUM(N33:U33) -> 14300 | W33: =M33-V33 -> 29700 | X33: =(E33+F33)*12% -> 3600 | Y33: =(E33+F33)*3% -> 900 | Z33: 1/3 | AA33: =A33&B33 -> 46174P G U N Wimalasooriya
A34: 46174 | B34: N M A G M Peiris | C34: 16 | D34: Assistant Branch Maneger | E34: 41500 | F34: 3500 | G34: 17000 | H34: 8000 | I34: 30380 | J34: 0 | K34: 1000 | L34: 2242.5 | M34: =SUM(E34:L34) -> 103622.5 | N34: =(E34+F34)*8% -> 3600 | O34: 5000 | P34: 0 | Q34: 5000 | R34: 1200 | S34: 0 | T34: 2242.5 | U34: 0 | V34: =SUM(N34:U34) -> 17042.5 | W34: =M34-V34 -> 86580 | X34: =(E34+F34)*12% -> 5400 | Y34: =(E34+F34)*3% -> 1350 | Z34: 1/8 | AA34: =A34&B34 -> 46174N M A G M Peiris
A35: 46174 | B35: K R T Hemantha | C35: 17 | D35: Field Executive | E35: 31500 | F35: 3500 | G35: 7500 | H35: 5000 | I35: 30380 | J35: 10000 | K35: 1000 | L35: 1050 | M35: =SUM(E35:L35) -> 89930 | N35: =(E35+F35)*8% -> 2800 | O35: 8000 | P35: 0 | Q35: 10000 | R35: 900 | S35: 0 | T35: 1050 | U35: 0 | V35: =SUM(N35:U35) -> 22750 | W35: =M35-V35 -> 67180 | X35: =(E35+F35)*12% -> 4200 | Y35: =(E35+F35)*3% -> 1050 | Z35: 5/7 | AA35: =A35&B35 -> 46174K R T Hemantha
A36: 46174 | B36: W M H M Weerasinghe | C36: 18 | D36: Assistant Accountant | E36: 51500 | F36: 3500 | G36: 21000 | H36: 0 | I36: 10000 | J36: 0 | K36: 1000 | L36: 1000 | M36: =SUM(E36:L36) -> 88000 | N36: =(E36+F36)*8% -> 4400 | O36: 0 | P36: 0 | Q36: 10000 | R36: 2100 | S36: 0 | T36: 1000 | U36: 0 | V36: =SUM(N36:U36) -> 17500 | W36: =M36-V36 -> 70500 | X36: =(E36+F36)*12% -> 6600 | Y36: =(E36+F36)*3% -> 1650 | Z36: 4/10 | AA36: =A36&B36 -> 46174W M H M Weerasinghe
A37: 46174 | B37: R W D S Wijerathna | C37: 19 | D37: Field Executive | E37: 36500 | F37: 3500 | G37: 7500 | H37: 5000 | I37: 30380 | J37: 10000 | K37: 1000 | L37: 8500 | M37: =SUM(E37:L37) -> 102380 | N37: =(E37+F37)*8% -> 3200 | O37: 0 | P37: 0 | Q37: 8333.33 | R37: 1000 | S37: 0 | T37: 8500 | U37: 0 | V37: =SUM(N37:U37) -> 21033.33 | W37: =M37-V37 -> 81346.67 | X37: =(E37+F37)*12% -> 4800 | Y37: =(E37+F37)*3% -> 1200 | Z37: 9/12 | AA37: =A37&B37 -> 46174R W D S Wijerathna
A38: 46174 | B38: S Wathmi Sankalpana | C38: 21 | D38: Trainee Account Clark | E38: 26500 | F38: 3500 | G38: 0 | H38: 0 | I38: 5000 | J38: 0 | K38: 1000 | L38: 1000 | M38: =SUM(E38:L38) -> 37000 | N38: =(E38+F38)*8% -> 2400 | O38: 10000 | P38: 0 | Q38: 6000 | R38: 540 | S38: 0 | T38: 1000 | U38: 0 | V38: =SUM(N38:U38) -> 19940 | W38: =M38-V38 -> 17060 | X38: =(E38+F38)*12% -> 3600 | Y38: =(E38+F38)*3% -> 900 | Z38: 3/5 | AA38: =A38&B38 -> 46174S Wathmi Sankalpana
A39: 46174 | B39: E M P P W O R K Jayawardana | C39: 22 | D39: Trainee Field Executive | E39: 26500 | F39: 3500 | G39: 5000 | H39: 2760 | I39: 26040 | J39: 10000 | K39: 1000 | L39: 4850 | M39: =SUM(E39:L39) -> 79650 | N39: =(E39+F39)*8% -> 2400 | O39: 0 | P39: 0 | Q39: 5000 | R39: 2100 | S39: 0 | T39: 4850 | U39: 0 | V39: =SUM(N39:U39) -> 14350 | W39: =M39-V39 -> 65300 | X39: =(E39+F39)*12% -> 3600 | Y39: =(E39+F39)*3% -> 900 | Z39: 3/16 | AA39: =A39&B39 -> 46174E M P P W O R K Jayawardana
A40: 46174 | B40: T M R L B Thennakoon | C40: 23 | D40: Trainee Field Executive | E40: 26500 | F40: 3500 | G40: 7000 | H40: 5000 | I40: 26040 | J40: 0 | K40: 1000 | L40: 3420 | M40: =SUM(E40:L40) -> 72460 | N40: =(E40+F40)*8% -> 2400 | O40: 6000 | P40: 0 | Q40: 10000 | R40: 600 | S40: 0 | T40: 3420 | U40: 0 | V40: =SUM(N40:U40) -> 22420 | W40: =M40-V40 -> 50040 | X40: =(E40+F40)*12% -> 3600 | Y40: =(E40+F40)*3% -> 900 | Z40: 4/5 | AA40: =A40&B40 -> 46174T M R L B Thennakoon
...
